Workbook
Name __mth2: [1]Adm!$G$31

Sheet 初语货表
A1: 款号 | B1: 类目 | C1: 日常价 | D1: 达播价 | E1: 佣金 | F1: 颜色 | G1: 材质
A2: 8613041 | B2: 针织衫 | C2: 179 | D2: 159 | E2: 20% | F2: 黑色,灰色 | G2: 50.8%粘纤 29.8%聚酯纤维 19.4%锦纶
A3: 8633052 | B3: 针织衫 | C3: 169 | D3: 149 | E3: 20% | F3: 深灰色 | G3: 0
A4: 8633013 | B4: 针织衫 | C4: 229 | D4: 209 | E4: 20% | F4: 薄荷绿,灰色,蓝色 | G4: 40.8%粘纤 34.1%锦纶 25.1%聚酯纤维
A5: 8613049 | B5: 针织衫 | C5: 169 | D5: 149 | E5: 20% | F5: 藏青间条,橄榄绿,灰色 | G5: 面料：29.2%聚酯纤维 25.9%腈纶 23.3%粘纤 21.6%锦纶
A6: 8633040 | B6: 针织衫 | C6: 199 | D6: 179 | E6: 20% | F6: 灰色,克莱因蓝 | G6: 44.8%锦纶 34.7%粘纤 20.5%聚酯纤维
A7: 8633018 | B7: 针织衫 | C7: 199 | D7: 169 | E7: 20% | F7: 粉色,克莱因蓝 | G7: 37.6%聚酯纤维 36.7%腈纶 21.2%锦纶 4.5%绵羊毛
A8: 8623029 | B8: 针织衫 | C8: 179 | D8: 149 | E8: 20% | F8: 天蓝色 | G8: 天蓝色：83.0%粘纤 17.0%聚酯纤维 浅粉色/米白色：84.6%再生纤维素纤维 15.4%聚酯纤维
A9: 8633046 | B9: 针织衫 | C9: 169 | D9: 149 | E9: 20% | F9: 淡粉色,淡蓝色 | G9: 0
A10: 8633051 | B10: 针织衫 | C10: 169 | D10: 149 | E10: 20% | F10: 黄绿条纹,咖色条纹 | G10: 0
A11: KB8633069 | B11: 针织衫 | C11: 189 | D11: 169 | E11: 20% | F11: 芥末绿,米白色 | G11: 0
A12: 8623043 | B12: 针织衫 | C12: 159 | D12: 139 | E12: 20% | F12: 浅蓝色,水粉色 | G12: 面料：86.0%粘纤 14.0%聚酯纤维
A13: 8633064 | B13: 针织衫 | C13: 169 | D13: 149 | E13: 20% | F13: 米白间条,深宝蓝间条 | G13: 0
A14: 8623110 | B14: 针织衫 | C14: 179 | D14: 129 | E14: 20% | F14: 灰紫色,蓝橙色 | G14: 82.0%再生纤维素纤维 18.0%锦纶
A15: 8623069 | B15: 针织衫 | C15: 179 | D15: 139 | E15: 20% | F15: 白色,红色,蓝色,绿色 | G15: 66.0%粘纤 34.0%锦纶
A16: 8623070 | B16: 针织衫 | C16: 189 | D16: 129 | E16: 20% | F16: 藏青色,鹅黄色,蓝色 | G16: 69.3%粘纤 30.7%锦纶
A17: 8623073 | B17: 针织衫 | C17: 159 | D17: 139 | E17: 20% | F17: 红色,蓝色,米白色 | G17: 83.5%莱赛尔 16.5%锦纶
A18: 8623089 | B18: 针织衫 | C18: 159 | D18: 109 | E18: 20% | F18: 粉黄色,粉蓝色,粉色 | G18: 82.4%粘纤 17.6%锦纶
A19: 8623017 | B19: 针织衫 | C19: 189 | D19: 109 | E19: 20% | F19: 深花灰,天蓝色 | G19: 67.5%粘纤 19.5%锦纶 13.0%聚酯纤维
A20: KB8633028 | B20: 针织衫 | C20: 159 | D20: 129 | E20: 20% | F20: 淡绿色,米白色,天蓝色 | G20: 86.8%再生纤维素纤维 13.2%聚酯纤维
A21: 8623045 | B21: 针织衫 | C21: 169 | D21: 139 | E21: 20% | F21: 艾绿色,黑色,米白色,浅蓝色 | G21: 56.9%腈纶 31.2%莱赛尔 11.9%亚麻 黑色:53.4%腈纶 36.7%莱赛尔 9.9%亚麻
A22: 8623042 | B22: 针织衫 | C22: 179 | D22: 149 | E22: 20% | F22: 藏青色,米杏色,浅粉色 | G22: 89.3%莱赛尔 10.7%锦纶
A23: 8523068 | B23: 针织衫 | C23: 139 | D23: 139 | E23: 20% | F23: 天蓝色、米杏色、深蓝色 | G23: 100%棉
A24: 8623014 | B24: 针织衫 | C24: 199 | D24: 149 | E24: 20% | F24: 藏青色,米白色,星钻蓝 | G24: 59.1%聚酯纤维 40.9%粘纤
A25: 8623087 | B25: 针织衫 | C25: 169 | D25: 129 | E25: 20% | F25: 艾绿色,藏青,灰色 | G25: 藏青 艾绿色：82.8%粘纤 17.2%锦纶 灰色：81.8%再生纤维素纤维 18.2%锦纶
A26: 8523015 | B26: 针织衫 | C26: 209 | D26: 99 | E26: 20% | F26: 100%粘纤 | G26: 黑色、米白色、安可拉红
A27: 8627029 | B27: 休闲裤 | C27: 159 | D27: 139 | E27: 20% | F27: 黑色-常规版,黑色-娇小版,深灰色-常规版,深灰色-娇小版 | G27: 主料：97.7%聚酯纤维 2.3%氨纶
A28: 8617006 | B28: 休闲裤 | C28: 189 | D28: 159 | E28: 20% | F28: 白色,黑色,卡其色 | G28: 面料：100%聚酯纤维
A29: 8627035 | B29: 休闲裤 | C29: 169 | D29: 149 | E29: 20% | F29: 黑色,米白色,暮云灰 | G29: 面料：49.7%棉 42.9%聚酯纤维 7.4%氨纶
A30: 8627047 | B30: 休闲裤 | C30: 179 | D30: 159 | E30: 20% | F30: 白色,浅灰色 | G30: 主料：100%聚酯纤维
A31: 8637007 | B31: 休闲裤 | C31: 199 | D31: 179 | E31: 20% | F31: 安可拉红,白色 | G31: 主料：100%聚酯纤维
A32: 8637006 | B32: 休闲裤 | C32: 199 | D32: 179 | E32: 20% | F32: 暗橙色,驼黄色 | G32: 主料：100%聚酯纤维
... A35: 8627034 | B35: 休闲裤 | C35: 179 | D35: 149 | E35: 20% | F35: 米白色,深卡其 | G35: 主料：71.1%聚酯纤维 28.9%锦纶
A36: 8627021 | B36: 休闲裤 | C36: 229 | D36: 159 | E36: 20% | F36: 橄榄绿,米杏色,天蓝色
A37: 8527028 | B37: 休闲裤 | C37: 189 | D37: 159 | E37: 20% | F37: 浅米杏、深宝蓝 | G37: 46.0%莱赛尔 38.7%粘纤 8.9%锦纶 6.4%亚麻
A38: 8617004 | B38: 休闲裤 | C38: 179 | D38: 129 | E38: 20% | F38: 白色,黑色,克莱因蓝 | G38: 0
A39: 8630008 | B39: 休闲裤 | C39: 229 | D39: 209 | E39: 20% | F39: 黑色 | G39: 面料：100%粘纤(涂层除外) 里料：100%聚酯纤维
A40: 8637012 | B40: 休闲裤 | C40: 189 | D40: 169 | E40: 20% | F40: 卡其色,深咖色 | G40: 主料：100%棉
A41: 8634003 | B41: 卫衣 | C41: 189 | D41: 169 | E41: 20% | F41: 黑色,枣红色 | G41: 主料：84.6%棉 15.4%聚酯纤维
A42: 8634025 | B42: 卫衣 | C42: 229 | D42: 209 | E42: 20% | F42: 深咖色 | G42: 主料：面层： 64.5%棉 35.5%聚酯纤维(含胶)底层： 100%聚酯纤维 印花料：74.6%莱赛尔 25.4%锦纶
...

Sheet 茵曼货表
A1: 款号 | B1: 类目 | C1: 日常价 | D1: 达播价 | E1: 佣金 | F1: 颜色 | G1: 材质
A2: 28628324 | B2: 配件 | C2: 59 | D2: 39 | E2: 0.2 | F2: 天蓝色、浅咖色、米白色、绿色、黄色 | G2: 100%粘纤 规格：100cm*42cm | H2: =MATCH(A2,[4]茵曼库存!$A:$A,0) -> 2
A3: 18625120 | B3: 针织衫 | C3: 229 | D3: 129 | E3: 0.2 | F3: 咖色、宝蓝色 | G3: 面料：62.5%粘纤 37.5%锦纶 | H3: =MATCH(A3,[4]茵曼库存!$A:$A,0) -> 3
A4: 18525140H1 | B4: 针织衫 | C4: 179 | D4: 129 | E4: 0.2 | F4: 多色 | H4: =MATCH(A4,[4]茵曼库存!$A:$A,0) -> 4
A5: F18627944 | B5: 针织衫 | C5: 199 | D5: 129 | E5: 0.2 | F5: 米杏色 | G5: 面料：66.6%粘纤 33.4%聚酯纤维 | H5: =MATCH(A5,[4]茵曼库存!$A:$A,0) -> 5
A6: W18618743 | B6: 针织衫 | C6: 259 | D6: 149 | E6: 0.2 | F6: 天空蓝、浅米黄 | G6: 面料：41.4%聚酯纤维 29.6%锦纶 29.0%粘纤 | H6: =MATCH(A6,[4]茵曼库存!$A:$A,0) -> 6
A7: 18528632 | B7: 针织衫 | C7: 239 | D7: 169 | E7: 0.2 | F7: 杏色 | G7: 面料：100%腈纶 | H7: =MATCH(A7,[4]茵曼库存!$A:$A,0) -> 7
A8: W18525322 | B8: 针织衫 | C8: 299 | D8: 169 | E8: 0.2 | F8: 星空蓝 | G8: 面料：75.0%聚酯纤维（含聚酯薄膜纤维） 18.5%粘纤 6.5%锦纶 | H8: =MATCH(A8,[4]茵曼库存!$A:$A,0) -> 8
A9: 18424047 | B9: 针织衫 | C9: 199 | D9: 139 | E9: 0.2 | F9: 蓝色、藕粉色 | G9: 面料：46.2%聚酯纤维 30.6%粘纤 23.2%锦纶 | H9: =MATCH(A9,[4]茵曼库存!$A:$A,0) -> 9
A10: D18628693 | B10: 针织衫 | C10: 169 | D10: 149 | E10: 0.2 | F10: 黄色、灰色、绿色、杏色、粉色 | G10: 38.9%再生纤维素纤维31.5%锦纶21.3%腈纶8.3%亚麻 | H10: =MATCH(A10,[4]茵曼库存!$A:$A,0) -> 11
A11: D18628827 | B11: 针织衫 | C11: 169 | D11: 149 | E11: 0.2 | F11: 黄色、灰色、粉色 | G11: 57.4%再生纤维素纤维 30.7%腈纶 11.9%亚麻 | H11: =MATCH(A11,[4]茵曼库存!$A:$A,0) -> 12
A12: D18628603 | B12: 针织衫 | C12: 179 | D12: 159 | E12: 0.2 | F12: 蓝色、杏色、豆绿 | G12: 69.1%粘纤30.9%锦纶 | H12: =MATCH(A12,[4]茵曼库存!$A:$A,0) -> 13
A13: D18628867 | B13: 针织衫 | C13: 169 | D13: 149 | E13: 0.2 | F13: 肉粉色 | G13: 外层：100%粘纤 内层：81.4%粘纤 18.6%锦纶 | H13: =MATCH(A13,[4]茵曼库存!$A:$A,0) -> 14
A14: D18628519 | B14: 针织衫 | C14: 169 | D14: 149 | E14: 0.2 | F14: 黄色、紫色、灰、粉色 | G14: 41.0%腈纶23.8%莱赛尔16.1%锦纶9.6%聚酯纤维9.5%亚麻 | H14: =MATCH(A14,[4]茵曼库存!$A:$A,0) -> 15
A15: D18618792 | B15: 针织衫 | C15: 169 | D15: 149 | E15: 0.2 | F15: 浅黄色、湖蓝色、大象灰 | G15: 100%棉 | H15: =MATCH(A15,[4]茵曼库存!$A:$A,0) -> 16
A16: D18628829 | B16: 针织衫 | C16: 159 | D16: 139 | E16: 0.2 | F16: 克莱因蓝 | G16: 72.6%粘纤27.4%聚酯纤维 | H16: =MATCH(A16,[4]茵曼库存!$A:$A,0) -> 17
A17: 1863001 | B17: 针织衫 | C17: 259 | D17: 179 | E17: 0.2 | F17: 浅紫色、宝蓝色、黄色、克莱因蓝 | G17: 黄色/宝蓝色/浅紫色 面料：31.6%聚酯纤维 31.4%腈纶 20.4%再生纤维素纤维 16.6%锦纶 (装饰部分除外) 克莱因蓝 面料：30.9%聚酯纤维 24.7%粘纤 24.4%腈纶 20.0%锦纶 (装饰部分除外) | H17: =MATCH(A17,[4]茵曼库存!$A:$A,0) -> 18
A18: 18637120 | B18: 针织衫 | C18: 199 | D18: 159.15 | E18: 0.2 | F18: 白黑条、黑白条纹 | G18: 黑白条纹 面料：57.9%聚酯纤维 20.3%腈纶 16.9%锦纶 4.9%绵羊毛 白黑条 面料：47.7%聚酯纤维 28.9%腈纶 18.6%锦纶 4.8%绵羊毛 | H18: =MATCH(A18,[4]茵曼库存!$A:$A,0) -> 19
A19: W18637061 | B19: 针织衫 | C19: 229 | D19: 149 | E19: 0.2 | F19: =VLOOKUP(A19,[2]Sheet1!$A:$G,7,FALSE) -> 贵族灰、米白色、燕麦色 | H19: =MATCH(A19,[4]茵曼库存!$A:$A,0) -> 20
A20: 18637207 | B20: 针织衫 | C20: 279 | D20: 199 | E20: 0.2 | F20: =VLOOKUP(A20,[2]Sheet1!$A:$G,7,FALSE) -> 藏青、黄色 | H20: =MATCH(A20,[4]茵曼库存!$A:$A,0) -> 21
A21: W18538192 | B21: 羊毛衫 | C21: 299 | D21: 199 | E21: 0.2 | F21: =VLOOKUP(A21,[2]Sheet1!$A:$G,7,FALSE) -> 米杏色、贵族灰、午夜黑、燕麦色、克莱因蓝 | G21: =MATCH(A21,[3]茵曼货表!$B:$B,0) -> #N/A | H21: =MATCH(A21,[4]茵曼库存!$A:$A,0) -> 22
A22: 18627629 | B22: 长袖衬衣 | C22: 239 | D22: 169 | E22: 0.2 | F22: 透气黄、珍珠白、薰衣草紫、冰川蓝、冰川粉 | G22: 面料：96.2%莱赛尔3.8%亚麻 | H22: =MATCH(A22,[4]茵曼库存!$A:$A,0) -> 23
A23: 18322228 | B23: 长袖衬衣 | C23: 229 | D23: 149 | E23: 0.2 | F23: 浅蓝色、浅绿色、丁香紫、鹅黄色、霜白色、薄荷绿、粉红色 | G23: 面料：84.4%莱赛尔15.6%聚酯纤维 | H23: =MATCH(A23,[4]茵曼库存!$A:$A,0) -> 24
A24: 18424138 | B24: 长袖衬衣 | C24: 239 | D24: 149 | E24: 0.2 | F24: 丁香粉清水绿 | G24: 面料： 84.5%莱赛尔 15.5%锦纶 | H24: =MATCH(A24,[4]茵曼库存!$A:$A,0) -> 25
A25: 18627948 | B25: 长袖衬衣 | C25: 347.5 | D25: 169 | E25: 0.2 | F25: 粉红色、香芋紫梦幻蓝 | G25: 面料：85.3%莱赛尔 14.7%聚酯纤维 | H25: =MATCH(A25,[4]茵曼库存!$A:$A,0) -> 26
A26: 18424160 | B26: 长袖衬衣 | C26: 219 | D26: 149 | E26: 0.2 | F26: 豆绿色\藕粉色、浅杏色 | G26: 面料：100%锦纶 | H26: =MATCH(A26,[4]茵曼库存!$A:$A,0) -> 27
A27: 18438094 | B27: 长袖衬衣 | C27: 179.9 | D27: 139 | E27: 0.2 | F27: 罗兰紫、珍珠白、卡其色、深酒红 | G27: 75.9% 棉 + 21% 锦纶 + 3.1% 氨纶，弹力舒适耐磨。修身版型显腿长，搭 T 恤休闲、配衬衫通勤，百搭实用！ | H27: =MATCH(A27,[4]茵曼库存!$A:$A,0) -> 28
A28: 18637636 | B28: 衬衣 | C28: 199 | D28: 139 | E28: 0.2 | F28: 浅紫色、皮粉色、珍珠白、水蓝色 | G28: 面料:63.8%聚酯纤维 36.2%棉 | H28: =MATCH(A28,[4]茵曼库存!$A:$A,0) -> 29
A29: 18637052 | B29: 衬衣 | C29: 219 | D29: 159 | E29: 0.2 | F29: 浅紫色、鹅黄色、海蓝色 | G29: 面料:100%棉 | H29: =MATCH(A29,[4]茵曼库存!$A:$A,0) -> 30
A30: 18637538 | B30: 衬衣 | C30: 239 | D30: 169 | E30: 0.2 | F30: 浅蓝色、米白色 | G30: 面料：100%棉 （花边除外） | H30: =MATCH(A30,[4]茵曼库存!$A:$A,0) -> 31
A31: 18637466 | B31: 衬衣 | C31: 239 | D31: 169 | E31: 0.2 | F31: 紫色、珍珠白 | G31: 面料：100%棉 （花边除外） | H31: =MATCH(A31,[4]茵曼库存!$A:$A,0) -> 32
A32: 18637480 | B32: 衬衣 | C32: 269 | D32: 179 | E32: 0.2 | F32: 浅蓝色、珍珠白 | G32: 面料：100%棉（花边除外） | H32: =MATCH(A32,[4]茵曼库存!$A:$A,0) -> 33
A33: 18637053 | B33: 衬衣 | C33: 259 | D33: 210.15 | E33: 0.2 | F33: 米杏色、釉蓝色 | G33: 面料:100%棉 | H33: =MATCH(A33,[4]茵曼库存!$A:$A,0) -> 34
A34: K18637810 | B34: 衬衣 | C34: 269 | D34: 189 | E34: 0.2 | F34: 米白色 | G34: 面料：底布：100%棉 绣花线：100%棉 领口花边：100%聚酯纤维 | H34: =MATCH(A34,[4]茵曼库存!$A:$A,0) -> 35
A35: W18637136 | B35: 衬衣 | C35: 299 | D35: 184.35 | E35: 0.2 | F35: 珍珠白 | G35: 面料/花边：100%棉 | H35: =MATCH(A35,[4]茵曼库存!$A:$A,0) -> 36
A36: 18637010 | B36: 衬衣 | C36: 279 | D36: 227.15 | E36: 0.2 | F36: 米白色 | G36: 面料：100%棉（花边除外） | H36: =MATCH(A36,[4]茵曼库存!$A:$A,0) -> 37
A37: K18637369 | B37: 衬衣 | C37: 269 | D37: -10 | E37: 0.2 | F37: 珍珠白、姜黄色 | G37: 面料：100%棉 （花边除外） | H37: =MATCH(A37,[4]茵曼库存!$A:$A,0) -> 38
A38: W18518278 | B38: 长袖衬衣 | C38: 269 | D38: 199 | E38: 0.2 | F38: 多色 | G38: 面料：100%棉 | H38: =MATCH(A38,[4]茵曼库存!$A:$A,0) -> 39
A39: 18618116 | B39: 长袖衬衣 | C39: 209 | D39: 159 | E39: 0.2 | F39: 多色 | G39: 面料：55.0%棉 45.0%莱赛尔 | H39: =MATCH(A39,[4]茵曼库存!$A:$A,0) -> 40
A40: 18625006 | B40: 长袖衬衣 | C40: 397.5 | D40: 149 | E40: 0.2 | F40: 盐白色、浅紫色 | G40: 浅水蓝/珍珠白/米白色/面料：100%棉（花边除外） 象牙白面料：56.5%棉 43.5%莱赛尔（花边除外） | H40: =MATCH(A40,[4]茵曼库存!$A:$A,0) -> 41
...
